Workbook

Sheet TRANSACCIONES
A1: Fecha | B1: Tipo | C1: Categoría | D1: Descripción | E1: Cuenta Origen | F1: Entidad | G1: Factura # | H1: Monto CRC | I1: Monto USD | J1: Tipo Cambio | K1: Método Pago | L1: Estado | M1: IVA % | N1: Ref. Bancaria | O1: Notas | P1: Creado Por | Q1: Fecha Creación | R1: Modificado Por | S1: ⚠️ Duplicados | T1: ID
J2: 540 | Q2: =NOW() | S2: =IF( COUNTIFS( $A:$A, A2, $E:$E, E2, $I:$I, I2 ) > 1, "⚠️ POSIBLE DUPLICADO", "" ) | T2: =ROW()-1

Sheet EFECTIVO
A1: CONTROL DE EFECTIVO, BANCOS Y TARJETAS DE CRÉDITO
A3: 🏦 CUENTAS BANCARIAS (ACTIVOS)
A4: Cuenta | B4: N° Completo | C4: Tipo | D4: Moneda | E4: Saldo 12/Nov | F4: Ingresos | G4: Egresos | H4: Saldo Actual | I4: Uso
A5: BNCR CRC Ahorros (***8618) | B5: 100-01-000-188618-3 | C5: Banco | D5: CRC | E5: 211.24 | F5: 0 | G5: 0 | H5: =E5+F5+G5 | I5: NEGOCIO
A6: BNCR USD Ahorros (***1066) | B6: 100-02-087-601066-4 | C6: Banco | D6: USD | E6: 1087.37 | F6: 0 | G6: 0 | H6: =E6+F6+G6 | I6: NEGOCIO
A7: BNCR CRC Corriente (***2186) | B7: 200-01-087-042186-9 | C7: Banco | D7: CRC | E7: 28950.5 | F7: 0 | G7: 0 | H7: =E7+F7+G7 | I7: NEGOCIO/RESERVAS
A8: BNCR USD Corriente (***9589) | B8: 200-02-087-009589-4 | C8: Banco | D8: USD | E8: 0.43 | F8: 0 | G8: 0 | H8: =E8+F8+G8 | I8: PERSONAL
A9: BNCR USD Corriente (***1112) | B9: 200-02-087-011112-1 | C9: Banco | D9: USD | E9: 21.84 | F9: 0 | G9: 0 | H9: =E9+F9+G9 | I9: PERSONAL
A10: Promerica CRC SINPE (***1708) | B10: 10000003881708 | C10: Banco | D10: CRC | E10: 1090 | F10: 0 | G10: 0 | H10: =E10+F10+G10 | I10: NEGOCIO
A11: Promerica USD Ahorros (***1691) | B11: 20000003881691 | C11: Banco | D11: USD | E11: 0 | F11: 0 | G11: 0 | H11: =E11+F11+G11 | I11: NEGOCIO
A12: Promerica CRC CC Corp (***4229) | B12: 30000003904229 | C12: Banco | D12: CRC | E12: 0 | F12: 0 | G12: 0 | H12: =E12+F12+G12 | I12: NEGOCIO
A13: Promerica USD CC Corp (***1774) | B13: 40000003881774 | C13: Banco | D13: USD | E13: 2276.44 | F13: 0 | G13: 0 | H13: =E13+F13+G13 | I13: NEGOCIO
A14: TOTAL BANCOS (USD equivalente) | E14: =SUMIF(D5:D13,"USD",E5:E13)+SUMIF(D5:D13,"CRC",E5:E13)/517.5 | F14: =SUM(F5:F13) | G14: =SUM(G5:G13) | H14: =SUM(H5:H13)
A16: 💳 TARJETAS DE CRÉDITO (PASIVOS - DEUDAS)
A17: Tarjeta | B17: Titular | C17: Saldo USD | D17: Saldo CRC | E17: Equiv. USD Total | F17: Pagos | G17: Cargos | H17: Saldo Actual | I17: Estrategia
A18: BNCR VISA ***3519 (Alvaro) | B18: Alvaro | C18: 3864.9 | D18: 0 | E18: =C18+(D18/517.5) | F18: 0 | G18: 0 | H18: =E18+F18+G18 | I18: Pago total mensual
A19: BNCR VISA ***9837 (Alvaro) | B19: Alvaro | C19: 3299.01 | D19: 0 | E19: =C19+(D19/517.5) | F19: 0 | G19: 0 | H19: =E19+F19+G19 | I19: Pago mínimo × 1.5
A20: BNCR VISA ***6386 (Alejandra) | B20: Alejandra | C20: 5195.07 | D20: 0 | E20: =C20+(D20/517.5) | F20: 0 | G20: 0 | H20: =E20+F20+G20 | I20: Pago mínimo × 1.5
A21: BNCR MC ***8759 (Alvaro) | B21: Alvaro | C21: 0 | D21: 863830 | E21: =C21+(D21/517.5) | F21: 0 | G21: 0 | H21: =E21+F21+G21 | I21: Pago mínimo × 1.5
A22: BAC VISA ***9550 (Alvaro) | B22: Alvaro | C22: 2508.75 | D22: 0 | E22: =C22+(D22/517.5) | F22: 0 | G22: 0 | H22: =E22+F22+G22 | I22: Pago mínimo × 1.5
A23: TOTAL TARJETAS (PASIVOS) | C23: =SUM(C18:C22) | D23: =SUM(D18:D22) | E23: =SUM(E18:E22) | F23: =SUM(F18:F22) | G23: =SUM(G18:G22) | H23: =SUM(H18:H22)
A25: 💰 EFECTIVO NETO (Bancos - Tarjetas) | F25: =H14-H23
A27: 💡 NOTAS:
A28: • Saldos al 12 de Noviembre 2025
A29: • Columnas 'Ingresos', 'Egresos', 'Pagos' y 'Cargos' se conectarán automáticamente a TRANSACCIONES
A30: • Tipo de cambio usado: ₡517.5 por $1 USD
A31: • EFECTIVO NETO REAL (12/Nov): $3,444.54 en bancos - $16,536 en tarjetas = -$13,091.46 (CRISIS)

Sheet DASHBOARD
B2: DASHBOARD FINANCIERO
B3: Última actualización: | C3: =NOW()
B5: 💰 EFECTIVO DISPONIBLE | E5: 🚨 ALERTAS CRÍTICAS
B6: Total Efectivo (USD): | C6: =EFECTIVO!G13 | E6: Duplicados: | F6: =COUNTIF(TRANSACCIONES!S:S, "⚠️ POSIBLE DUPLICADO")
E7: Pendientes: | F7: =COUNTIF(TRANSACCIONES!L:L, "PENDIENTE")
B8: ⏱️ DÍAS DE COBERTURA | E8: Sin categoría: | F8: =COUNTBLANK(TRANSACCIONES!C:C) - 1
B9: Gasto Diario Promedio: | C9: =SUMIFS(TRANSACCIONES!I:I, TRANSACCIONES!B:B, "GASTO OPERATIVO", TRANSACCIONES!L:L, "COMPLETADA") / 30
B10: Días de Cobertura: | C10: =IF(C9>0, C6/C9, 0) | D10: =IF(C10<15, "🚨 CRÍTICO", IF(C10<30, "⚠️ PRECAUCIÓN", "✅ SALUDABLE"))
B12: 🏆 TOP 5 CLIENTES (Noviembre)
B13: Cliente | C13: Facturado USD
B14: Grupo Acción Comercial S.A. | C14: 1689.04
B15: VWR International Ltda | C15: 1400
B16: Alfipac (Almacén Fiscal Pacífico) | C16: 761.05
B17: 3-102-887892 SRL | C17: 691.56
B18: Waipio S.A. | C18: 687.27

Sheet ENTIDADES_ALIAS
A1: SISTEMA DE NORMALIZACIÓN DE ENTIDADES
A2: 💡 Esta hoja permite normalizar nombres de clientes, proveedores y bancos que aparecen con variaciones
A4: Tipo | B4: Nombre Estándar | C4: Alias 1 | D4: Alias 2 | E4: Alias 3 | F4: Alias 4 | G4: Alias 5 | H4: Categoría | I4: Notas | J4: Última Actualización
A5: Cliente | B5: Grupo Acción Comercial S.A. | C5: Grupo Acción Comercial | D5: GACS | H5: VIP | I5: Facturación Nov: $1689.04 | J5: 13/11/2025
A6: Cliente | B6: VWR International Ltda | C6: VWR International | D6: IL | H6: VIP | I6: Facturación Nov: $1400.00 | J6: 13/11/2025
A7: Cliente | B7: Alfipac (Almacén Fiscal Pacífico) | D7: A(FP | H7: VIP | I7: Facturación Nov: $761.05 | J7: 13/11/2025
A8: Cliente | B8: 3-102-887892 SRL | H8: Regular | I8: Facturación Nov: $691.56 | J8: 13/11/2025
A9: Cliente | B9: Waipio S.A. | C9: Waipio | H9: Regular | I9: Facturación Nov: $687.27 | J9: 13/11/2025
A10: Cliente | B10: Centro Integral Oncología CIO SRL | D10: CIO | H10: Regular | I10: Facturación Nov: $687.05 | J10: 13/11/2025
A11: Cliente | B11: Ortodoncia de la Cruz | D11: OC | H11: Regular | I11: Facturación Nov: $494.50 | J11: 13/11/2025
A12: Cliente | B12: Global Automotriz GACR S.A. | C12: Global Automotriz GACR | D12: GAGS | H12: Regular | I12: Facturación Nov: $439.61 | J12: 13/11/2025
A13: Cliente | B13: Solusa Consolidators | H13: Regular | I13: Facturación Nov: $378.35 | J13: 13/11/2025
A14: Cliente | B14: Cemso | H14: Regular | I14: Facturación Nov: $333.92 | J14: 13/11/2025
A15: Cliente | B15: Acacia (Asoc. CR Agencias Carga) | D15: A(AC | H15: Regular | I15: Facturación Nov: $333.35 | J15: 13/11/2025
A16: Cliente | B16: Rodriguez Rojas Carlos Humberto | D16: RRCH | H16: Regular | I16: Facturación Nov: $282.50 | J16: 13/11/2025
A17: Cliente | B17: Supply Net C.R.W.H S.A. | C17: Supply Net C.R.W.H | D17: SCS | H17: Regular | I17: Facturación Nov: $276.85 | J17: 13/11/2025
A18: Cliente | B18: Operation Managment Tierra Magnifica | D18: OMTM | H18: Regular | I18: Facturación Nov: $209.06 | J18: 13/11/2025
A19: Cliente | B19: Gentra de Costa Rica S.A. | C19: Gentra de Costa Rica | D19: GCRS | H19: Regular | I19: Facturación Nov: $183.63 | J19: 13/11/2025
A20: Cliente | B20: Sevilla Navarro Edgar | D20: SNE | H20: Regular | I20: Facturación Nov: $169.50 | J20: 13/11/2025
A21: Cliente | B21: Gomez Ajoy Edgar Luis | D21: GAEL | H21: Regular | I21: Facturación Nov: $113.00 | J21: 13/11/2025
A22: Cliente | B22: Melendez Morales Monica | D22: MMM | H22: Regular | I22: Facturación Nov: $113.00 | J22: 13/11/2025
A23: Cliente | B23: Bandogo Soluciones Tecnológicas S.A. | C23: Bandogo Soluciones Tecnológicas | D23: BSTS | H23: Regular | I23: Facturación Nov: $67.80 | J23: 13/11/2025
A24: Cliente | B24: CPF Servicios Radiológicos S.A. | C24: CPF Servicios Radiológicos | D24: SRS | H24: Regular | I24: Facturación Nov: $56.50 | J24: 13/11/2025
A25: Cliente | B25: Ortodec S.A. | C25: Ortodec | H25: Regular | I25: Facturación Nov: $56.50 | J25: 13/11/2025
A26: Cliente | B26: Perez Morales Francisco | D26: PMF | H26: Regular | I26: Facturación Nov: $42.38 | J26: 13/11/2025
A27: Proveedor | B27: Intcomex Costa Rica | H27: Principal | J27: 13/11/2025
A28: Proveedor | B28: Eurocomp S.A. | H28: Principal | J28: 13/11/2025
A29: Proveedor | B29: CompuEconómicos | H29: Principal | J29: 13/11/2025
A30: Proveedor | B30: TD Synex | H30: Principal | J30: 13/11/2025
A31: Proveedor | B31: ICD Soft | H31: Principal | J31: 13/11/2025
A32: Banco | B32: BNCR CRC Ahorros (***8618) | H32: Banco | I32: Moneda: CRC | J32: 13/11/2025
A33: Banco | B33: BNCR USD Ahorros (***1066) | H33: Banco | I33: Moneda: USD | J33: 13/11/2025
A34: Banco | B34: BNCR CRC Corriente (***2186) | H34: Banco | I34: Moneda: CRC | J34: 13/11/2025
A35: Banco | B35: BNCR USD Corriente (***9589) | H35: Banco | I35: Moneda: USD | J35: 13/11/2025
A36: Banco | B36: BNCR USD Corriente (***1112) | H36: Banco | I36: Moneda: USD | J36: 13/11/2025
A37: Banco | B37: Promerica CRC SINPE (***1708) | H37: Banco | I37: Moneda: CRC | J37: 13/11/2025
A38: Banco | B38: Promerica USD Ahorros (***1691) | H38: Banco | I38: Moneda: USD | J38: 13/11/2025
A39: Banco | B39: Promerica CRC CC Corp (***4229) | H39: Banco | I39: Moneda: CRC | J39: 13/11/2025
A40: Banco | B40: Promerica USD CC Corp (***1774) | H40: Banco | I40: Moneda: USD | J40: 13/11/2025
A43: 📋 INSTRUCCIONES:
...

Sheet CONFIG
A1: CONFIGURACIÓN DEL SISTEMA
A3: Versión | B3: 3.0.0 MVP
A4: Fecha Creación | B4: 13/11/2025 00:19
A5: Propietario | B5: Alvaro Velasco - AVN (AlvaroVelascoNet)
A6: Tipo Cambio por Defecto | B6: 517.50
A7: Período Fiscal | B7: 2025
A8: Mes Activo | B8: Noviembre 2025
